<?xml version="1.0" encoding="utf-8"?>
<!-- 
     Last modified: Oct 11, 2025
     Notes (Billie)
        1. Fix the frame of xjc force sensor to make it the same with real hardware

     Last modified: Sep 1, 2025
     Notes (Muzhi): 
        1. Add vicon center frame

     Last modified: Aug 29, 2025
     Notes (Muzhi): 
        1. Change joint limits within [-pi, pi] as the encoder is single-round
        2. Update joint limits of waist and head

     Last modified: Aug 25, 2025
     Notes (Muzhi): 
        1. Fix joint limits for arm and gripper
    
     Last modified: Aug 25, 2025
     Notes (Zhiao): 
        1. Add textured STL based on beta1.0_v2_20250822_no_texture.urdf

     Last modified: Aug 22, 2025
     Notes (Muzhi): 
        1. Add textured STL based on beta1.0_v2_20250822_no_texture.urdf
-->
<robot
  name="hillbot_beta1.0_v2">

  <link
    name="left-link_arm_base">
    <inertial>
      <origin
        xyz="-2.177E-05 -3.226E-06 0.021818"
        rpy="0 0 0" />
      <mass
        value="1.6029" />
      <inertia
        ixx="0.0015278"
        ixy="-1.5672E-07"
        ixz="-1.8033E-06"
        iyy="0.0015302"
        iyz="-2.7424E-07"
        izz="0.00164" />
    </inertial>
    <visual>
      <origin
        xyz="0 0 0"
        rpy="0 0 0" />
      <geometry>
        <mesh
          filename="meshes/left-link_arm_base.STL" />
      </geometry>
    </visual>
    <collision>
      <origin
        xyz="0 0 0"
        rpy="0 0 0" />
      <geometry>
        <mesh
          filename="meshes/left-link_arm_base.STL" />
      </geometry>
    </collision>
  </link>
  
  <link
    name="left-link_arm_1">
    <inertial>
      <origin
        xyz="-0.006159 8.9872E-06 0.034906"
        rpy="0 0 0" />
      <mass
        value="0.62221" />
      <inertia
        ixx="0.0011121"
        ixy="7.2469E-08"
        ixz="0.00029532"
        iyy="0.0014513"
        iyz="2.1321E-07"
        izz="0.0013836" />
    </inertial>
    <visual>
      <origin
        xyz="0 0 0"
        rpy="0 0 0" />
      <geometry>
        <mesh
          filename="meshes/left-link_arm_1.STL" />
      </geometry>
    </visual>
    <collision>
      <origin
        xyz="0 0 0"
        rpy="0 0 0" />
      <geometry>
        <mesh
          filename="meshes/left-link_arm_1.STL" />
      </geometry>
    </collision>
  </link>

  <joint
    name="left-joint_arm_1"
    type="revolute">
    <origin
      xyz="0 0 0.048"
      rpy="0 0 0" />
    <parent
      link="left-link_arm_base" />
    <child
      link="left-link_arm_1" />
    <axis
      xyz="0 0 1" />
    <limit
      lower="-3.141"
      upper="3.141"
      effort="100"
      velocity="1" />
  </joint>

  <link
    name="left-link_arm_2">
    <inertial>
      <origin
        xyz="-1.0077E-05 0.057266 -0.040519"
        rpy="0 0 0" />
      <mass
        value="3.335" />
      <inertia
        ixx="0.0050711"
        ixy="-2.7631E-06"
        ixz="1.0382E-07"
        iyy="0.0032897"
        iyz="0.0001035"
        izz="0.0052288" />
    </inertial>
    <visual>
      <origin
        xyz="0 0 0"
        rpy="0 0 0" />
      <geometry>
        <mesh
          filename="meshes/left-link_arm_2.STL" />
      </geometry>
    </visual>
    <collision>
      <origin
        xyz="0 0 0"
        rpy="0 0 0" />
      <geometry>
        <mesh
          filename="meshes/left-link_arm_2.STL" />
      </geometry>
    </collision>
  </link>

  <joint
    name="left-joint_arm_2"
    type="revolute">
    <origin
      xyz="-0.046 0 0.077001"
      rpy="1.5708 0 -1.5708" />
    <parent
      link="left-link_arm_1" />
    <child
      link="left-link_arm_2" />
    <axis
      xyz="0 0 1" />
    <limit
      lower="-1.92"
      upper="1.536"
      effort="100"
      velocity="1" />
  </joint>

  <link
    name="left-link_arm_3">
    <inertial>
      <origin
        xyz="-0.031101 1.4455E-07 0.0806"
        rpy="0 0 0" />
      <mass
        value="0.8901" />
      <inertia
        ixx="0.0031463"
        ixy="-5.5317E-09"
        ixz="0.00081849"
        iyy="0.0033105"
        iyz="-1.5446E-08"
        izz="0.0010721" />
    </inertial>
    <visual>
      <origin
        xyz="0 0 0"
        rpy="0 0 0" />
      <geometry>
        <mesh
          filename="meshes/left-link_arm_3.STL" />
      </geometry>
    </visual>
    <collision>
      <origin
        xyz="0 0 0"
        rpy="0 0 0" />
      <geometry>
        <mesh
          filename="meshes/left-link_arm_3.STL" />
      </geometry>
    </collision>
  </link>

  <joint
    name="left-joint_arm_3"
    type="revolute">
    <origin
      xyz="0 0.164 -0.046"
      rpy="0.081886 1.5708 1.6527" />
    <parent
      link="left-link_arm_2" />
    <child
      link="left-link_arm_3" />
    <axis
      xyz="0 0 1" />
    <limit
      lower="-3.141"
      upper="3.141"
      effort="100"
      velocity="1" />
  </joint>

  <link
    name="left-link_arm_4">
    <inertial>
      <origin
        xyz="-3.2344E-05 0.027786 -0.032327"
        rpy="0 0 0" />
      <mass
        value="1.9108" />
      <inertia
        ixx="0.002356"
        ixy="-1.3929E-06"
        ixz="-2.4343E-06"
        iyy="0.0016002"
        iyz="2.6552E-05"
        izz="0.0022494" />
    </inertial>
    <visual>
      <origin
        xyz="0 0 0"
        rpy="0 0 0" />
      <geometry>
        <mesh
          filename="meshes/left-link_arm_4.STL" />
      </geometry>
    </visual>
    <collision>
      <origin
        xyz="0 0 0"
        rpy="0 0 0" />
      <geometry>
        <mesh
          filename="meshes/left-link_arm_4.STL" />
      </geometry>
    </collision>
  </link>

  <joint
    name="left-joint_arm_4"
    type="revolute">
    <origin
      xyz="-0.038497 0 0.165"
      rpy="1.5708 0 -1.5708" />
    <parent
      link="left-link_arm_3" />
    <child
      link="left-link_arm_4" />
    <axis
      xyz="0 0 1" />
    <limit
      lower="-2.618"
      upper="2.339"
      effort="100"
      velocity="1" />
  </joint>

  <link
    name="left-link_arm_5">
    <inertial>
      <origin
        xyz="0.0055557 -7.6462E-07 0.058391"
        rpy="0 0 0" />
      <mass
        value="0.38604" />
      <inertia
        ixx="0.00047968"
        ixy="2.974E-08"
        ixz="0.00010993"
        iyy="0.00066901"
        iyz="-3.7792E-08"
        izz="0.00051992" />
    </inertial>
    <visual>
      <origin
        xyz="0 0 0"
        rpy="0 0 0" />
      <geometry>
        <mesh
          filename="meshes/left-link_arm_5.STL" />
      </geometry>
    </visual>
    <collision>
      <origin
        xyz="0 0 0"
        rpy="0 0 0" />
      <geometry>
        <mesh
          filename="meshes/left-link_arm_5.STL" />
      </geometry>
    </collision>
  </link>

  <joint
    name="left-joint_arm_5"
    type="revolute">
    <origin
      xyz="0 0.133 -0.0385"
      rpy="-1.5708 1.5708 0" />
    <parent
      link="left-link_arm_4" />
    <child
      link="left-link_arm_5" />
    <axis
      xyz="0 0 1" />
    <limit
      lower="-3.141"
      upper="3.141"
      effort="100"
      velocity="1" />
  </joint>

  <link
    name="left-link_arm_6">
    <inertial>
      <origin
        xyz="0.0036019 0.027995 -0.039393"
        rpy="0 0 0" />
      <mass
        value="1.0489" />
      <inertia
        ixx="0.00090582"
        ixy="-2.8023E-05"
        ixz="2.6101E-06"
        iyy="0.0007786"
        iyz="2.7804E-05"
        izz="0.00090569" />
    </inertial>
    <visual>
      <origin
        xyz="0 0 0"
        rpy="0 0 0" />
      <geometry>
        <mesh
          filename="meshes/left-link_arm_6.STL" />
      </geometry>
    </visual>
    <collision>
      <origin
        xyz="0 0 0"
        rpy="0 0 0" />
      <geometry>
        <mesh
          filename="meshes/left-link_arm_6.STL" />
      </geometry>
    </collision>
  </link>

  <joint
    name="left-joint_arm_6"
    type="revolute">
    <origin
      xyz="-0.043005 0 0.107"
      rpy="1.5708 0 -1.5708" />
    <parent
      link="left-link_arm_5" />
    <child
      link="left-link_arm_6" />
    <axis
      xyz="0 0 1" />
    <limit
      lower="-1.518"
      upper="1.518"
      effort="100"
      velocity="1" />
  </joint>

  <link
    name="left-link_arm_7">
    <inertial>
      <origin
        xyz="3.7857E-06 0.035894 -0.048679"
        rpy="0 0 0" />
      <mass
        value="0.31289" />
      <inertia
        ixx="0.0004681"
        ixy="-7.8174E-09"
        ixz="-1.1472E-09"
        iyy="0.00044068"
        iyz="7.7636E-05"
        izz="0.00027572" />
    </inertial>
    <visual>
      <origin
        xyz="0 0 0"
        rpy="0 0 0" />
      <geometry>
        <mesh
          filename="meshes/left-link_arm_7.STL" />
      </geometry>
    </visual>
    <collision>
      <origin
        xyz="0 0 0"
        rpy="0 0 0" />
      <geometry>
        <mesh
          filename="meshes/left-link_arm_7.STL" />
      </geometry>
    </collision>
  </link>

  <joint
    name="left-joint_arm_7"
    type="revolute">
    <origin
      xyz="0.043002 0.056 -0.043002"
      rpy="-1.5708 1.5708 -1.5708" />
    <parent
      link="left-link_arm_6" />
    <child
      link="left-link_arm_7" />
    <axis
      xyz="0 0 -1" />
    <limit
      lower="-1.466"
      upper="1.466"
      effort="100"
      velocity="1" />
  </joint>
  
  <!-- <joint
    name="left-joint_ee_ft_sensor"
    type="fixed">
    <origin
      xyz="0 0.061001 -0.042983"
      rpy="-1.5708 2.35619 0.0" />
    <parent
      link="left-link_arm_7" />
    <child
      link="left-link_ee_ft_sensor" />
    <axis
      xyz="0 0 0" />
  </joint>
  <link
    name="left-link_ee_camera">
    <inertial>
      <origin
        xyz="-0.00019967 0.10944 0.04187"
        rpy="0 0 0" />
      <mass
        value="0.1612" />
      <inertia
        ixx="4.7106E-05"
        ixy="4.0957E-07"
        ixz="-2.0629E-07"
        iyy="0.00016172"
        iyz="-1.0092E-05"
        izz="0.0001819" />
    </inertial>
    <visual>
      <origin
        xyz="0 0 0"
        rpy="0 0 0" />
      <geometry>
        <mesh
          filename="meshes/left-link_ee_camera.STL" />
      </geometry>
    </visual>
    <collision>
      <origin
        xyz="0 0 0"
        rpy="0 0 0" />
      <geometry>
        <mesh
          filename="meshes/left-link_ee_camera.STL" />
      </geometry>
    </collision>
  </link>
  <joint
    name="left-joint_ee_camera"
    type="fixed">
    <origin
      xyz="0 0.061001 -0.042983"
      rpy="1.5708 -0.00023035 3.1416" />
    <parent
      link="left-link_arm_7" />
    <child
      link="left-link_ee_camera" />
    <axis
      xyz="0 0 0" />
  </joint> -->

</robot>